[2024-07-15T21:06:52.529+0000] {taskinstance.py:1956} INFO - Dependencies all met for dep_context=non-requeueable deps ti=<TaskInstance: generated_dag.run_script_task scheduled__2024-07-15T00:21:00+00:00 [queued]>
[2024-07-15T21:06:52.543+0000] {taskinstance.py:1956} INFO - Dependencies all met for dep_context=requeueable deps ti=<TaskInstance: generated_dag.run_script_task scheduled__2024-07-15T00:21:00+00:00 [queued]>
[2024-07-15T21:06:52.544+0000] {taskinstance.py:2170} INFO - Starting attempt 1 of 2
[2024-07-15T21:06:52.719+0000] {taskinstance.py:2191} INFO - Executing <Task(PythonOperator): run_script_task> on 2024-07-15 00:21:00+00:00
[2024-07-15T21:06:52.738+0000] {standard_task_runner.py:60} INFO - Started process 1290 to run task
[2024-07-15T21:06:52.749+0000] {standard_task_runner.py:87} INFO - Running: ['***', 'tasks', 'run', 'generated_dag', 'run_script_task', 'scheduled__2024-07-15T00:21:00+00:00', '--job-id', '52', '--raw', '--subdir', 'DAGS_FOLDER/generated_dag.py', '--cfg-path', '/tmp/tmpngisbdkw']
[2024-07-15T21:06:52.753+0000] {standard_task_runner.py:88} INFO - Job 52: Subtask run_script_task
[2024-07-15T21:06:52.843+0000] {task_command.py:423} INFO - Running <TaskInstance: generated_dag.run_script_task scheduled__2024-07-15T00:21:00+00:00 [running]> on host e66935bdb0d8
[2024-07-15T21:06:52.962+0000] {taskinstance.py:2480} INFO - Exporting env vars: AIRFLOW_CTX_DAG_OWNER='***' AIRFLOW_CTX_DAG_ID='generated_dag' AIRFLOW_CTX_TASK_ID='run_script_task' AIRFLOW_CTX_EXECUTION_DATE='2024-07-15T00:21:00+00:00' AIRFLOW_CTX_TRY_NUMBER='1' AIRFLOW_CTX_DAG_RUN_ID='scheduled__2024-07-15T00:21:00+00:00'
[2024-07-15T21:06:53.664+0000] {taskinstance.py:2698} ERROR - Task failed with exception
Traceback (most recent call last):
  File "/home/airflow/.local/lib/python3.8/site-packages/airflow/models/taskinstance.py", line 433, in _execute_task
    result = execute_callable(context=context, **execute_callable_kwargs)
  File "/home/airflow/.local/lib/python3.8/site-packages/airflow/operators/python.py", line 199, in execute
    return_value = self.execute_callable()
  File "/home/airflow/.local/lib/python3.8/site-packages/airflow/operators/python.py", line 216, in execute_callable
    return self.python_callable(*self.op_args, **self.op_kwargs)
  File "/opt/airflow/dags/generated_dag.py", line 7, in run_script
    subprocess.run(['python', '/opt/airflow/dags/generated_code.py'], check=True)
  File "/usr/local/lib/python3.8/subprocess.py", line 516, in run
    raise CalledProcessError(retcode, process.args,
subprocess.CalledProcessError: Command '['python', '/opt/airflow/dags/generated_code.py']' returned non-zero exit status 1.
[2024-07-15T21:06:53.685+0000] {taskinstance.py:1138} INFO - Marking task as UP_FOR_RETRY. dag_id=generated_dag, task_id=run_script_task, execution_date=20240715T002100, start_date=20240715T210652, end_date=20240715T210653
[2024-07-15T21:06:53.702+0000] {standard_task_runner.py:107} ERROR - Failed to execute job 52 for task run_script_task (Command '['python', '/opt/airflow/dags/generated_code.py']' returned non-zero exit status 1.; 1290)
[2024-07-15T21:06:53.723+0000] {local_task_job_runner.py:234} INFO - Task exited with return code 1
[2024-07-15T21:06:53.761+0000] {taskinstance.py:3280} INFO - 0 downstream tasks scheduled from follow-on schedule check
[2024-07-16T00:06:37.403+0000] {taskinstance.py:1956} INFO - Dependencies all met for dep_context=non-requeueable deps ti=<TaskInstance: generated_dag.run_script_task scheduled__2024-07-15T00:21:00+00:00 [queued]>
[2024-07-16T00:06:37.423+0000] {taskinstance.py:1956} INFO - Dependencies all met for dep_context=requeueable deps ti=<TaskInstance: generated_dag.run_script_task scheduled__2024-07-15T00:21:00+00:00 [queued]>
[2024-07-16T00:06:37.425+0000] {taskinstance.py:2170} INFO - Starting attempt 1 of 2
[2024-07-16T00:06:37.460+0000] {taskinstance.py:2191} INFO - Executing <Task(PythonOperator): run_script_task> on 2024-07-15 00:21:00+00:00
[2024-07-16T00:06:37.472+0000] {standard_task_runner.py:60} INFO - Started process 3040 to run task
[2024-07-16T00:06:37.487+0000] {standard_task_runner.py:87} INFO - Running: ['***', 'tasks', 'run', 'generated_dag', 'run_script_task', 'scheduled__2024-07-15T00:21:00+00:00', '--job-id', '1098', '--raw', '--subdir', 'DAGS_FOLDER/generated_dag.py', '--cfg-path', '/tmp/tmp09xi496g']
[2024-07-16T00:06:37.498+0000] {standard_task_runner.py:88} INFO - Job 1098: Subtask run_script_task
[2024-07-16T00:06:37.627+0000] {task_command.py:423} INFO - Running <TaskInstance: generated_dag.run_script_task scheduled__2024-07-15T00:21:00+00:00 [running]> on host 3f7dfc26d15f
[2024-07-16T00:06:37.782+0000] {taskinstance.py:2480} INFO - Exporting env vars: AIRFLOW_CTX_DAG_OWNER='***' AIRFLOW_CTX_DAG_ID='generated_dag' AIRFLOW_CTX_TASK_ID='run_script_task' AIRFLOW_CTX_EXECUTION_DATE='2024-07-15T00:21:00+00:00' AIRFLOW_CTX_TRY_NUMBER='1' AIRFLOW_CTX_DAG_RUN_ID='scheduled__2024-07-15T00:21:00+00:00'
[2024-07-16T00:06:39.251+0000] {taskinstance.py:2698} ERROR - Task failed with exception
Traceback (most recent call last):
  File "/home/airflow/.local/lib/python3.8/site-packages/airflow/models/taskinstance.py", line 433, in _execute_task
    result = execute_callable(context=context, **execute_callable_kwargs)
  File "/home/airflow/.local/lib/python3.8/site-packages/airflow/operators/python.py", line 199, in execute
    return_value = self.execute_callable()
  File "/home/airflow/.local/lib/python3.8/site-packages/airflow/operators/python.py", line 216, in execute_callable
    return self.python_callable(*self.op_args, **self.op_kwargs)
  File "/opt/airflow/dags/generated_dag.py", line 7, in run_script
    subprocess.run(['python', '/opt/airflow/dags/generated_code.py'], check=True)
  File "/usr/local/lib/python3.8/subprocess.py", line 516, in run
    raise CalledProcessError(retcode, process.args,
subprocess.CalledProcessError: Command '['python', '/opt/airflow/dags/generated_code.py']' returned non-zero exit status 1.
[2024-07-16T00:06:39.286+0000] {taskinstance.py:1138} INFO - Marking task as UP_FOR_RETRY. dag_id=generated_dag, task_id=run_script_task, execution_date=20240715T002100, start_date=20240716T000637, end_date=20240716T000639
[2024-07-16T00:06:39.323+0000] {standard_task_runner.py:107} ERROR - Failed to execute job 1098 for task run_script_task (Command '['python', '/opt/airflow/dags/generated_code.py']' returned non-zero exit status 1.; 3040)
[2024-07-16T00:06:39.358+0000] {local_task_job_runner.py:234} INFO - Task exited with return code 1
[2024-07-16T00:06:39.411+0000] {taskinstance.py:3280} INFO - 0 downstream tasks scheduled from follow-on schedule check
