[2024-07-15T21:06:51.870+0000] {taskinstance.py:1956} INFO - Dependencies all met for dep_context=non-requeueable deps ti=<TaskInstance: generated_dag.run_script_task scheduled__2024-07-15T00:18:00+00:00 [queued]>
[2024-07-15T21:06:51.884+0000] {taskinstance.py:1956} INFO - Dependencies all met for dep_context=requeueable deps ti=<TaskInstance: generated_dag.run_script_task scheduled__2024-07-15T00:18:00+00:00 [queued]>
[2024-07-15T21:06:51.885+0000] {taskinstance.py:2170} INFO - Starting attempt 1 of 2
[2024-07-15T21:06:51.907+0000] {taskinstance.py:2191} INFO - Executing <Task(PythonOperator): run_script_task> on 2024-07-15 00:18:00+00:00
[2024-07-15T21:06:51.917+0000] {standard_task_runner.py:60} INFO - Started process 1275 to run task
[2024-07-15T21:06:51.921+0000] {standard_task_runner.py:87} INFO - Running: ['***', 'tasks', 'run', 'generated_dag', 'run_script_task', 'scheduled__2024-07-15T00:18:00+00:00', '--job-id', '49', '--raw', '--subdir', 'DAGS_FOLDER/generated_dag.py', '--cfg-path', '/tmp/tmp556u9mul']
[2024-07-15T21:06:51.927+0000] {standard_task_runner.py:88} INFO - Job 49: Subtask run_script_task
[2024-07-15T21:06:52.006+0000] {task_command.py:423} INFO - Running <TaskInstance: generated_dag.run_script_task scheduled__2024-07-15T00:18:00+00:00 [running]> on host e66935bdb0d8
[2024-07-15T21:06:52.114+0000] {taskinstance.py:2480} INFO - Exporting env vars: AIRFLOW_CTX_DAG_OWNER='***' AIRFLOW_CTX_DAG_ID='generated_dag' AIRFLOW_CTX_TASK_ID='run_script_task' AIRFLOW_CTX_EXECUTION_DATE='2024-07-15T00:18:00+00:00' AIRFLOW_CTX_TRY_NUMBER='1' AIRFLOW_CTX_DAG_RUN_ID='scheduled__2024-07-15T00:18:00+00:00'
[2024-07-15T21:06:53.023+0000] {taskinstance.py:2698} ERROR - Task failed with exception
Traceback (most recent call last):
  File "/home/airflow/.local/lib/python3.8/site-packages/airflow/models/taskinstance.py", line 433, in _execute_task
    result = execute_callable(context=context, **execute_callable_kwargs)
  File "/home/airflow/.local/lib/python3.8/site-packages/airflow/operators/python.py", line 199, in execute
    return_value = self.execute_callable()
  File "/home/airflow/.local/lib/python3.8/site-packages/airflow/operators/python.py", line 216, in execute_callable
    return self.python_callable(*self.op_args, **self.op_kwargs)
  File "/opt/airflow/dags/generated_dag.py", line 7, in run_script
    subprocess.run(['python', '/opt/airflow/dags/generated_code.py'], check=True)
  File "/usr/local/lib/python3.8/subprocess.py", line 516, in run
    raise CalledProcessError(retcode, process.args,
subprocess.CalledProcessError: Command '['python', '/opt/airflow/dags/generated_code.py']' returned non-zero exit status 1.
[2024-07-15T21:06:53.040+0000] {taskinstance.py:1138} INFO - Marking task as UP_FOR_RETRY. dag_id=generated_dag, task_id=run_script_task, execution_date=20240715T001800, start_date=20240715T210651, end_date=20240715T210653
[2024-07-15T21:06:53.059+0000] {standard_task_runner.py:107} ERROR - Failed to execute job 49 for task run_script_task (Command '['python', '/opt/airflow/dags/generated_code.py']' returned non-zero exit status 1.; 1275)
[2024-07-15T21:06:53.105+0000] {local_task_job_runner.py:234} INFO - Task exited with return code 1
[2024-07-15T21:06:53.129+0000] {taskinstance.py:3280} INFO - 0 downstream tasks scheduled from follow-on schedule check
[2024-07-16T00:06:34.208+0000] {taskinstance.py:1956} INFO - Dependencies all met for dep_context=non-requeueable deps ti=<TaskInstance: generated_dag.run_script_task scheduled__2024-07-15T00:18:00+00:00 [queued]>
[2024-07-16T00:06:34.225+0000] {taskinstance.py:1956} INFO - Dependencies all met for dep_context=requeueable deps ti=<TaskInstance: generated_dag.run_script_task scheduled__2024-07-15T00:18:00+00:00 [queued]>
[2024-07-16T00:06:34.226+0000] {taskinstance.py:2170} INFO - Starting attempt 1 of 2
[2024-07-16T00:06:34.257+0000] {taskinstance.py:2191} INFO - Executing <Task(PythonOperator): run_script_task> on 2024-07-15 00:18:00+00:00
[2024-07-16T00:06:34.266+0000] {standard_task_runner.py:60} INFO - Started process 3017 to run task
[2024-07-16T00:06:34.277+0000] {standard_task_runner.py:87} INFO - Running: ['***', 'tasks', 'run', 'generated_dag', 'run_script_task', 'scheduled__2024-07-15T00:18:00+00:00', '--job-id', '1095', '--raw', '--subdir', 'DAGS_FOLDER/generated_dag.py', '--cfg-path', '/tmp/tmpkzmmpwct']
[2024-07-16T00:06:34.286+0000] {standard_task_runner.py:88} INFO - Job 1095: Subtask run_script_task
[2024-07-16T00:06:34.388+0000] {task_command.py:423} INFO - Running <TaskInstance: generated_dag.run_script_task scheduled__2024-07-15T00:18:00+00:00 [running]> on host 3f7dfc26d15f
[2024-07-16T00:06:34.618+0000] {taskinstance.py:2480} INFO - Exporting env vars: AIRFLOW_CTX_DAG_OWNER='***' AIRFLOW_CTX_DAG_ID='generated_dag' AIRFLOW_CTX_TASK_ID='run_script_task' AIRFLOW_CTX_EXECUTION_DATE='2024-07-15T00:18:00+00:00' AIRFLOW_CTX_TRY_NUMBER='1' AIRFLOW_CTX_DAG_RUN_ID='scheduled__2024-07-15T00:18:00+00:00'
[2024-07-16T00:06:36.529+0000] {taskinstance.py:2698} ERROR - Task failed with exception
Traceback (most recent call last):
  File "/home/airflow/.local/lib/python3.8/site-packages/airflow/models/taskinstance.py", line 433, in _execute_task
    result = execute_callable(context=context, **execute_callable_kwargs)
  File "/home/airflow/.local/lib/python3.8/site-packages/airflow/operators/python.py", line 199, in execute
    return_value = self.execute_callable()
  File "/home/airflow/.local/lib/python3.8/site-packages/airflow/operators/python.py", line 216, in execute_callable
    return self.python_callable(*self.op_args, **self.op_kwargs)
  File "/opt/airflow/dags/generated_dag.py", line 7, in run_script
    subprocess.run(['python', '/opt/airflow/dags/generated_code.py'], check=True)
  File "/usr/local/lib/python3.8/subprocess.py", line 516, in run
    raise CalledProcessError(retcode, process.args,
subprocess.CalledProcessError: Command '['python', '/opt/airflow/dags/generated_code.py']' returned non-zero exit status 1.
[2024-07-16T00:06:36.565+0000] {taskinstance.py:1138} INFO - Marking task as UP_FOR_RETRY. dag_id=generated_dag, task_id=run_script_task, execution_date=20240715T001800, start_date=20240716T000634, end_date=20240716T000636
[2024-07-16T00:06:36.895+0000] {standard_task_runner.py:107} ERROR - Failed to execute job 1095 for task run_script_task (Command '['python', '/opt/airflow/dags/generated_code.py']' returned non-zero exit status 1.; 3017)
[2024-07-16T00:06:36.940+0000] {local_task_job_runner.py:234} INFO - Task exited with return code 1
[2024-07-16T00:06:37.028+0000] {taskinstance.py:3280} INFO - 0 downstream tasks scheduled from follow-on schedule check
