[2024-07-15T21:21:59.108+0000] {taskinstance.py:1956} INFO - Dependencies all met for dep_context=non-requeueable deps ti=<TaskInstance: generated_dag.run_script_task scheduled__2024-07-14T00:30:00+00:00 [queued]>
[2024-07-15T21:21:59.116+0000] {taskinstance.py:1956} INFO - Dependencies all met for dep_context=requeueable deps ti=<TaskInstance: generated_dag.run_script_task scheduled__2024-07-14T00:30:00+00:00 [queued]>
[2024-07-15T21:21:59.117+0000] {taskinstance.py:2170} INFO - Starting attempt 2 of 2
[2024-07-15T21:21:59.132+0000] {taskinstance.py:2191} INFO - Executing <Task(PythonOperator): run_script_task> on 2024-07-14 00:30:00+00:00
[2024-07-15T21:21:59.137+0000] {standard_task_runner.py:60} INFO - Started process 1846 to run task
[2024-07-15T21:21:59.140+0000] {standard_task_runner.py:87} INFO - Running: ['***', 'tasks', 'run', 'generated_dag', 'run_script_task', 'scheduled__2024-07-14T00:30:00+00:00', '--job-id', '123', '--raw', '--subdir', 'DAGS_FOLDER/generated_dag.py', '--cfg-path', '/tmp/tmp3t2dgeh1']
[2024-07-15T21:21:59.143+0000] {standard_task_runner.py:88} INFO - Job 123: Subtask run_script_task
[2024-07-15T21:21:59.193+0000] {task_command.py:423} INFO - Running <TaskInstance: generated_dag.run_script_task scheduled__2024-07-14T00:30:00+00:00 [running]> on host e66935bdb0d8
[2024-07-15T21:21:59.261+0000] {taskinstance.py:2480} INFO - Exporting env vars: AIRFLOW_CTX_DAG_OWNER='***' AIRFLOW_CTX_DAG_ID='generated_dag' AIRFLOW_CTX_TASK_ID='run_script_task' AIRFLOW_CTX_EXECUTION_DATE='2024-07-14T00:30:00+00:00' AIRFLOW_CTX_TRY_NUMBER='2' AIRFLOW_CTX_DAG_RUN_ID='scheduled__2024-07-14T00:30:00+00:00'
[2024-07-15T21:21:59.291+0000] {taskinstance.py:2698} ERROR - Task failed with exception
Traceback (most recent call last):
  File "/home/airflow/.local/lib/python3.8/site-packages/airflow/models/taskinstance.py", line 433, in _execute_task
    result = execute_callable(context=context, **execute_callable_kwargs)
  File "/home/airflow/.local/lib/python3.8/site-packages/airflow/operators/python.py", line 199, in execute
    return_value = self.execute_callable()
  File "/home/airflow/.local/lib/python3.8/site-packages/airflow/operators/python.py", line 216, in execute_callable
    return self.python_callable(*self.op_args, **self.op_kwargs)
  File "/opt/airflow/dags/generated_dag.py", line 7, in run_script
    subprocess.run(['python', 'generated_code.py'], check=True)
  File "/usr/local/lib/python3.8/subprocess.py", line 516, in run
    raise CalledProcessError(retcode, process.args,
subprocess.CalledProcessError: Command '['python', 'generated_code.py']' returned non-zero exit status 2.
[2024-07-15T21:21:59.303+0000] {taskinstance.py:1138} INFO - Marking task as FAILED. dag_id=generated_dag, task_id=run_script_task, execution_date=20240714T003000, start_date=20240715T212159, end_date=20240715T212159
[2024-07-15T21:21:59.315+0000] {standard_task_runner.py:107} ERROR - Failed to execute job 123 for task run_script_task (Command '['python', 'generated_code.py']' returned non-zero exit status 2.; 1846)
[2024-07-15T21:21:59.353+0000] {local_task_job_runner.py:234} INFO - Task exited with return code 1
[2024-07-15T21:21:59.370+0000] {taskinstance.py:3280} INFO - 0 downstream tasks scheduled from follow-on schedule check
