[2024-07-15T21:06:36.621+0000] {taskinstance.py:1956} INFO - Dependencies all met for dep_context=non-requeueable deps ti=<TaskInstance: generated_dag.run_script_task scheduled__2024-07-15T00:07:00+00:00 [queued]>
[2024-07-15T21:06:36.642+0000] {taskinstance.py:1956} INFO - Dependencies all met for dep_context=requeueable deps ti=<TaskInstance: generated_dag.run_script_task scheduled__2024-07-15T00:07:00+00:00 [queued]>
[2024-07-15T21:06:36.643+0000] {taskinstance.py:2170} INFO - Starting attempt 2 of 2
[2024-07-15T21:06:36.674+0000] {taskinstance.py:2191} INFO - Executing <Task(PythonOperator): run_script_task> on 2024-07-15 00:07:00+00:00
[2024-07-15T21:06:36.685+0000] {standard_task_runner.py:60} INFO - Started process 1201 to run task
[2024-07-15T21:06:36.691+0000] {standard_task_runner.py:87} INFO - Running: ['***', 'tasks', 'run', 'generated_dag', 'run_script_task', 'scheduled__2024-07-15T00:07:00+00:00', '--job-id', '31', '--raw', '--subdir', 'DAGS_FOLDER/generated_dag.py', '--cfg-path', '/tmp/tmp07j4qvrm']
[2024-07-15T21:06:36.698+0000] {standard_task_runner.py:88} INFO - Job 31: Subtask run_script_task
[2024-07-15T21:06:36.811+0000] {task_command.py:423} INFO - Running <TaskInstance: generated_dag.run_script_task scheduled__2024-07-15T00:07:00+00:00 [running]> on host e66935bdb0d8
[2024-07-15T21:06:36.928+0000] {taskinstance.py:2480} INFO - Exporting env vars: AIRFLOW_CTX_DAG_OWNER='***' AIRFLOW_CTX_DAG_ID='generated_dag' AIRFLOW_CTX_TASK_ID='run_script_task' AIRFLOW_CTX_EXECUTION_DATE='2024-07-15T00:07:00+00:00' AIRFLOW_CTX_TRY_NUMBER='2' AIRFLOW_CTX_DAG_RUN_ID='scheduled__2024-07-15T00:07:00+00:00'
[2024-07-15T21:06:37.961+0000] {taskinstance.py:2698} ERROR - Task failed with exception
Traceback (most recent call last):
  File "/home/airflow/.local/lib/python3.8/site-packages/airflow/models/taskinstance.py", line 433, in _execute_task
    result = execute_callable(context=context, **execute_callable_kwargs)
  File "/home/airflow/.local/lib/python3.8/site-packages/airflow/operators/python.py", line 199, in execute
    return_value = self.execute_callable()
  File "/home/airflow/.local/lib/python3.8/site-packages/airflow/operators/python.py", line 216, in execute_callable
    return self.python_callable(*self.op_args, **self.op_kwargs)
  File "/opt/airflow/dags/generated_dag.py", line 7, in run_script
    subprocess.run(['python', '/opt/airflow/dags/generated_code.py'], check=True)
  File "/usr/local/lib/python3.8/subprocess.py", line 516, in run
    raise CalledProcessError(retcode, process.args,
subprocess.CalledProcessError: Command '['python', '/opt/airflow/dags/generated_code.py']' returned non-zero exit status 1.
[2024-07-15T21:06:37.980+0000] {taskinstance.py:1138} INFO - Marking task as FAILED. dag_id=generated_dag, task_id=run_script_task, execution_date=20240715T000700, start_date=20240715T210636, end_date=20240715T210637
[2024-07-15T21:06:38.003+0000] {standard_task_runner.py:107} ERROR - Failed to execute job 31 for task run_script_task (Command '['python', '/opt/airflow/dags/generated_code.py']' returned non-zero exit status 1.; 1201)
[2024-07-15T21:06:38.041+0000] {local_task_job_runner.py:234} INFO - Task exited with return code 1
[2024-07-15T21:06:38.245+0000] {taskinstance.py:3280} INFO - 0 downstream tasks scheduled from follow-on schedule check
[2024-07-16T00:06:23.402+0000] {taskinstance.py:1956} INFO - Dependencies all met for dep_context=non-requeueable deps ti=<TaskInstance: generated_dag.run_script_task scheduled__2024-07-15T00:07:00+00:00 [queued]>
[2024-07-16T00:06:23.420+0000] {taskinstance.py:1956} INFO - Dependencies all met for dep_context=requeueable deps ti=<TaskInstance: generated_dag.run_script_task scheduled__2024-07-15T00:07:00+00:00 [queued]>
[2024-07-16T00:06:23.422+0000] {taskinstance.py:2170} INFO - Starting attempt 2 of 2
[2024-07-16T00:06:23.446+0000] {taskinstance.py:2191} INFO - Executing <Task(PythonOperator): run_script_task> on 2024-07-15 00:07:00+00:00
[2024-07-16T00:06:23.457+0000] {standard_task_runner.py:60} INFO - Started process 2957 to run task
[2024-07-16T00:06:23.464+0000] {standard_task_runner.py:87} INFO - Running: ['***', 'tasks', 'run', 'generated_dag', 'run_script_task', 'scheduled__2024-07-15T00:07:00+00:00', '--job-id', '1084', '--raw', '--subdir', 'DAGS_FOLDER/generated_dag.py', '--cfg-path', '/tmp/tmpkxgtfq6c']
[2024-07-16T00:06:23.470+0000] {standard_task_runner.py:88} INFO - Job 1084: Subtask run_script_task
[2024-07-16T00:06:23.580+0000] {task_command.py:423} INFO - Running <TaskInstance: generated_dag.run_script_task scheduled__2024-07-15T00:07:00+00:00 [running]> on host 3f7dfc26d15f
[2024-07-16T00:06:23.733+0000] {taskinstance.py:2480} INFO - Exporting env vars: AIRFLOW_CTX_DAG_OWNER='***' AIRFLOW_CTX_DAG_ID='generated_dag' AIRFLOW_CTX_TASK_ID='run_script_task' AIRFLOW_CTX_EXECUTION_DATE='2024-07-15T00:07:00+00:00' AIRFLOW_CTX_TRY_NUMBER='2' AIRFLOW_CTX_DAG_RUN_ID='scheduled__2024-07-15T00:07:00+00:00'
[2024-07-16T00:06:25.036+0000] {taskinstance.py:2698} ERROR - Task failed with exception
Traceback (most recent call last):
  File "/home/airflow/.local/lib/python3.8/site-packages/airflow/models/taskinstance.py", line 433, in _execute_task
    result = execute_callable(context=context, **execute_callable_kwargs)
  File "/home/airflow/.local/lib/python3.8/site-packages/airflow/operators/python.py", line 199, in execute
    return_value = self.execute_callable()
  File "/home/airflow/.local/lib/python3.8/site-packages/airflow/operators/python.py", line 216, in execute_callable
    return self.python_callable(*self.op_args, **self.op_kwargs)
  File "/opt/airflow/dags/generated_dag.py", line 7, in run_script
    subprocess.run(['python', '/opt/airflow/dags/generated_code.py'], check=True)
  File "/usr/local/lib/python3.8/subprocess.py", line 516, in run
    raise CalledProcessError(retcode, process.args,
subprocess.CalledProcessError: Command '['python', '/opt/airflow/dags/generated_code.py']' returned non-zero exit status 1.
[2024-07-16T00:06:25.061+0000] {taskinstance.py:1138} INFO - Marking task as FAILED. dag_id=generated_dag, task_id=run_script_task, execution_date=20240715T000700, start_date=20240716T000623, end_date=20240716T000625
[2024-07-16T00:06:25.094+0000] {standard_task_runner.py:107} ERROR - Failed to execute job 1084 for task run_script_task (Command '['python', '/opt/airflow/dags/generated_code.py']' returned non-zero exit status 1.; 2957)
[2024-07-16T00:06:25.125+0000] {local_task_job_runner.py:234} INFO - Task exited with return code 1
[2024-07-16T00:06:25.163+0000] {taskinstance.py:3280} INFO - 0 downstream tasks scheduled from follow-on schedule check
