[2024-07-15T22:11:43.746+0000] {taskinstance.py:1956} INFO - Dependencies all met for dep_context=non-requeueable deps ti=<TaskInstance: generated_dag.run_script_task scheduled__2024-07-14T02:31:00+00:00 [queued]>
[2024-07-15T22:11:43.760+0000] {taskinstance.py:1956} INFO - Dependencies all met for dep_context=requeueable deps ti=<TaskInstance: generated_dag.run_script_task scheduled__2024-07-14T02:31:00+00:00 [queued]>
[2024-07-15T22:11:43.761+0000] {taskinstance.py:2170} INFO - Starting attempt 2 of 2
[2024-07-15T22:11:43.780+0000] {taskinstance.py:2191} INFO - Executing <Task(PythonOperator): run_script_task> on 2024-07-14 02:31:00+00:00
[2024-07-15T22:11:43.790+0000] {standard_task_runner.py:60} INFO - Started process 554 to run task
[2024-07-15T22:11:43.795+0000] {standard_task_runner.py:87} INFO - Running: ['***', 'tasks', 'run', 'generated_dag', 'run_script_task', 'scheduled__2024-07-14T02:31:00+00:00', '--job-id', '372', '--raw', '--subdir', 'DAGS_FOLDER/generated_dag.py', '--cfg-path', '/tmp/tmpklb58abl']
[2024-07-15T22:11:43.803+0000] {standard_task_runner.py:88} INFO - Job 372: Subtask run_script_task
[2024-07-15T22:11:43.898+0000] {task_command.py:423} INFO - Running <TaskInstance: generated_dag.run_script_task scheduled__2024-07-14T02:31:00+00:00 [running]> on host 91b894657735
[2024-07-15T22:11:43.999+0000] {taskinstance.py:2480} INFO - Exporting env vars: AIRFLOW_CTX_DAG_OWNER='***' AIRFLOW_CTX_DAG_ID='generated_dag' AIRFLOW_CTX_TASK_ID='run_script_task' AIRFLOW_CTX_EXECUTION_DATE='2024-07-14T02:31:00+00:00' AIRFLOW_CTX_TRY_NUMBER='2' AIRFLOW_CTX_DAG_RUN_ID='scheduled__2024-07-14T02:31:00+00:00'
[2024-07-15T22:11:44.943+0000] {taskinstance.py:2698} ERROR - Task failed with exception
Traceback (most recent call last):
  File "/home/airflow/.local/lib/python3.8/site-packages/airflow/models/taskinstance.py", line 433, in _execute_task
    result = execute_callable(context=context, **execute_callable_kwargs)
  File "/home/airflow/.local/lib/python3.8/site-packages/airflow/operators/python.py", line 199, in execute
    return_value = self.execute_callable()
  File "/home/airflow/.local/lib/python3.8/site-packages/airflow/operators/python.py", line 216, in execute_callable
    return self.python_callable(*self.op_args, **self.op_kwargs)
  File "/opt/airflow/dags/generated_dag.py", line 7, in run_script
    subprocess.run(['python', '/opt/airflow/dags/generated_code.py'], check=True)
  File "/usr/local/lib/python3.8/subprocess.py", line 516, in run
    raise CalledProcessError(retcode, process.args,
subprocess.CalledProcessError: Command '['python', '/opt/airflow/dags/generated_code.py']' returned non-zero exit status 1.
[2024-07-15T22:11:44.963+0000] {taskinstance.py:1138} INFO - Marking task as FAILED. dag_id=generated_dag, task_id=run_script_task, execution_date=20240714T023100, start_date=20240715T221143, end_date=20240715T221144
[2024-07-15T22:11:44.992+0000] {standard_task_runner.py:107} ERROR - Failed to execute job 372 for task run_script_task (Command '['python', '/opt/airflow/dags/generated_code.py']' returned non-zero exit status 1.; 554)
[2024-07-15T22:11:45.018+0000] {local_task_job_runner.py:234} INFO - Task exited with return code 1
[2024-07-15T22:11:45.058+0000] {taskinstance.py:3280} INFO - 0 downstream tasks scheduled from follow-on schedule check
