[2024-07-15T23:08:48.721+0000] {taskinstance.py:1956} INFO - Dependencies all met for dep_context=non-requeueable deps ti=<TaskInstance: generated_dag.run_script_task scheduled__2024-07-14T05:21:00+00:00 [queued]>
[2024-07-15T23:08:48.735+0000] {taskinstance.py:1956} INFO - Dependencies all met for dep_context=requeueable deps ti=<TaskInstance: generated_dag.run_script_task scheduled__2024-07-14T05:21:00+00:00 [queued]>
[2024-07-15T23:08:48.736+0000] {taskinstance.py:2170} INFO - Starting attempt 2 of 2
[2024-07-15T23:08:48.760+0000] {taskinstance.py:2191} INFO - Executing <Task(PythonOperator): run_script_task> on 2024-07-14 05:21:00+00:00
[2024-07-15T23:08:48.768+0000] {standard_task_runner.py:60} INFO - Started process 338 to run task
[2024-07-15T23:08:48.773+0000] {standard_task_runner.py:87} INFO - Running: ['***', 'tasks', 'run', 'generated_dag', 'run_script_task', 'scheduled__2024-07-14T05:21:00+00:00', '--job-id', '725', '--raw', '--subdir', 'DAGS_FOLDER/generated_dag.py', '--cfg-path', '/tmp/tmpbxgh9yqe']
[2024-07-15T23:08:48.779+0000] {standard_task_runner.py:88} INFO - Job 725: Subtask run_script_task
[2024-07-15T23:08:48.861+0000] {task_command.py:423} INFO - Running <TaskInstance: generated_dag.run_script_task scheduled__2024-07-14T05:21:00+00:00 [running]> on host 3f7dfc26d15f
[2024-07-15T23:08:48.972+0000] {taskinstance.py:2480} INFO - Exporting env vars: AIRFLOW_CTX_DAG_OWNER='***' AIRFLOW_CTX_DAG_ID='generated_dag' AIRFLOW_CTX_TASK_ID='run_script_task' AIRFLOW_CTX_EXECUTION_DATE='2024-07-14T05:21:00+00:00' AIRFLOW_CTX_TRY_NUMBER='2' AIRFLOW_CTX_DAG_RUN_ID='scheduled__2024-07-14T05:21:00+00:00'
[2024-07-15T23:08:49.945+0000] {taskinstance.py:2698} ERROR - Task failed with exception
Traceback (most recent call last):
  File "/home/airflow/.local/lib/python3.8/site-packages/airflow/models/taskinstance.py", line 433, in _execute_task
    result = execute_callable(context=context, **execute_callable_kwargs)
  File "/home/airflow/.local/lib/python3.8/site-packages/airflow/operators/python.py", line 199, in execute
    return_value = self.execute_callable()
  File "/home/airflow/.local/lib/python3.8/site-packages/airflow/operators/python.py", line 216, in execute_callable
    return self.python_callable(*self.op_args, **self.op_kwargs)
  File "/opt/airflow/dags/generated_dag.py", line 7, in run_script
    subprocess.run(['python', '/opt/airflow/dags/generated_code.py'], check=True)
  File "/usr/local/lib/python3.8/subprocess.py", line 516, in run
    raise CalledProcessError(retcode, process.args,
subprocess.CalledProcessError: Command '['python', '/opt/airflow/dags/generated_code.py']' returned non-zero exit status 1.
[2024-07-15T23:08:49.969+0000] {taskinstance.py:1138} INFO - Marking task as FAILED. dag_id=generated_dag, task_id=run_script_task, execution_date=20240714T052100, start_date=20240715T230848, end_date=20240715T230849
[2024-07-15T23:08:50.036+0000] {standard_task_runner.py:107} ERROR - Failed to execute job 725 for task run_script_task (Command '['python', '/opt/airflow/dags/generated_code.py']' returned non-zero exit status 1.; 338)
[2024-07-15T23:08:50.072+0000] {local_task_job_runner.py:234} INFO - Task exited with return code 1
[2024-07-15T23:08:50.115+0000] {taskinstance.py:3280} INFO - 0 downstream tasks scheduled from follow-on schedule check
